File: Specimen_RawData_1.csv
Time measurement (s),Primary load measurement (N),Extension (mm)
0,0.09471,0
0.1,-0.30999,-0.03985
0.2,-0.8547,-0.13008
0.3,-1.17489,-0.21386
0.4,-1.39844,-0.29739
0.5,-1.5061,-0.3805
0.6,-1.51319,-0.46411
0.7,-1.54131,-0.54695
0.8,-1.56805,-0.63074
0.9,-1.58688,-0.71365
1,-1.60718,-0.79732
1.1,-1.62789,-0.8806
1.2,-1.65758,-0.96386
1.3,-1.70741,-1.04748
1.4,-1.76219,-1.13036
1.5,-1.8068,-1.21418
1.6,-1.81037,-1.29686
1.7,-1.81605,-1.38072
1.8,-1.83791,-1.46355
1.9,-1.85431,-1.54741
2,-1.89416,-1.63051
2.1,-1.91988,-1.71389
2.2,-1.9406,-1.79739
2.3,-1.98659,-1.88023
2.4,-2.0024,-1.96412
2.5,-2.01895,-2.0469
2.6,-2.04608,-2.13078
2.7,-2.0589,-2.21364
2.8,-2.0728,-2.29724
2.9,-2.08194,-2.38041
3,-2.10873,-2.46368
3.1,-2.12307,-2.5475
3.2,-2.14521,-2.63036
3.3,-2.15998,-2.71414
3.4,-2.17119,-2.79683
3.5,-2.17728,-2.88075
3.6,-2.18897,-2.96378
3.7,-2.18363,-3.04726
3.8,-2.20746,-3.13053
3.9,-2.21693,-3.21378
4,-2.23392,-3.29755
4.1,-2.23941,-3.38039
4.2,-2.25135,-3.46409
4.3,-2.2432,-3.54695
4.4,-2.26712,-3.63077
4.5,-2.27399,-3.71375
4.6,-2.25943,-3.79739
4.7,-2.34422,-3.88053
4.8,-2.44783,-3.96376
4.9,-2.50446,-4.04741
5,-2.57847,-4.1304
5.1,-2.63299,-4.21429
5.2,-2.69579,-4.29687
5.3,-2.76157,-4.38068
5.4,-2.82567,-4.46363
5.5,-2.91702,-4.54736
5.6,-3.01084,-4.63051
5.7,-3.10022,-4.71383
5.8,-3.19412,-4.79745
5.9,-3.28252,-4.88031
6,-3.37613,-4.96421
6.1,-3.47347,-5.04697
6.2,-3.55982,-5.13081
6.3,-3.66409,-5.21359
6.4,-3.77306,-5.29724
6.5,-3.8629,-5.38047
6.6,-3.97091,-5.46373
6.7,-4.09006,-5.54745
6.8,-4.19629,-5.63034
6.9,-4.29509,-5.71411
7,-4.42074,-5.7969
7.1,-4.51813,-5.88083
7.2,-4.82641,-5.96365
7.3,-5.16398,-6.04726
7.4,-5.52696,-6.13047
7.5,-5.89066,-6.21381
7.6,-6.26484,-6.29749
7.7,-6.65681,-6.38032
7.8,-7.05213,-6.46417
7.9,-7.44185,-6.54678
8,-7.82205,-6.63077
8.1,-8.20663,-6.71365
8.2,-8.59841,-6.79724
8.3,-8.99719,-6.88051
8.4,-9.40997,-6.96379
8.5,-9.78804,-7.04729
8.6,-10.15335,-7.1303
8.7,-10.45831,-7.2142
8.8,-10.8163,-7.29689
8.9,-11.18252,-7.38069
9,-11.55768,-7.46351
9.1,-11.93893,-7.54727
9.2,-12.32188,-7.63038
9.3,-12.70359,-7.71389
9.4,-13.10505,-7.79748
9.5,-13.50113,-7.88027
9.6,-13.91574,-7.96408
9.7,-14.32424,-8.04689
9.8,-14.74096,-8.13076
9.9,-15.13335,-8.21349
10,-15.5554,-8.29734
10.1,-15.96348,-8.38068
10.2,-16.37699,-8.46375
10.3,-16.78372,-8.5474
10.4,-17.1988,-8.63033
10.5,-17.63019,-8.71418
10.6,-18.05857,-8.79682
10.7,-18.45137,-8.88076
10.8,-18.85988,-8.96361
10.9,-19.2607,-9.04725
11,-19.69897,-9.13054
11.1,-20.16047,-9.21397
11.2,-20.60267,-9.29746
11.3,-21.08281,-9.38027
11.4,-21.56386,-9.46418
11.5,-22.05151,-9.54697
11.6,-22.57504,-9.63079
11.7,-23.09326,-9.71364
11.8,-23.63386,-9.7974
11.9,-24.18905,-9.88054
12,-24.72253,-9.96378
12.1,-25.26517,-10.04755
12.2,-25.81528,-10.13024
12.3,-26.37363,-10.21407
12.4,-26.92856,-10.29679
12.5,-27.51213,-10.3808
12.6,-28.06053,-10.46367
12.7,-28.63554,-10.54725
12.8,-29.22411,-10.63055
12.9,-29.81505,-10.7138
13,-30.41779,-10.7975
13.1,-30.99327,-10.88041
13.2,-31.59046,-10.96414
13.3,-32.19158,-11.04684
13.4,-32.82714,-11.13071
13.5,-33.4211,-11.21361
13.6,-34.0169,-11.29733
13.7,-34.6491,-11.38056
13.8,-35.2841,-11.46385
13.9,-35.93057,-11.54743
14,-36.5253,-11.63035
14.1,-37.18652,-11.71422
14.2,-37.81371,-11.79683
14.3,-38.42937,-11.88073
14.4,-39.08324,-11.96357
14.5,-39.70507,-12.04727
14.6,-40.37408,-12.13045
14.7,-41.03695,-12.21381
14.8,-41.67868,-12.29754
14.9,-42.27409,-12.38025
15,-42.93746,-12.46409
15.1,-43.58661,-12.54692
15.2,-44.21799,-12.63066
15.3,-44.84506,-12.71358
15.4,-45.47,-12.7972
15.5,-46.08039,-12.88047
15.6,-46.68255,-12.96387
15.7,-47.27693,-13.04751
15.8,-47.90055,-13.13039
15.9,-48.58439,-13.21404
16,-49.22322,-13.29683
16.1,-49.89817,-13.38072
16.2,-50.56185,-13.46364
16.3,-51.23244,-13.54727
16.4,-51.92843,-13.63051
16.5,-52.58561,-13.71391
16.6,-53.2872,-13.7974
16.7,-53.98847,-13.88038
16.8,-54.66073,-13.96408
16.9,-55.34624,-14.04681
17,-56.03025,-14.13064
17.1,-56.73964,-14.21375
17.2,-57.40907,-14.29733
17.3,-58.08579,-14.38052
17.4,-58.79403,-14.46385
17.5,-59.49747,-14.54754
17.6,-60.15921,-14.63041
17.7,-60.86555,-14.71408
17.8,-61.56753,-14.79687
17.9,-62.25984,-14.88067
18,-62.96236,-14.9636
18.1,-63.6635,-15.0475
18.2,-64.37069,-15.13055
18.3,-65.07787,-15.21375
18.4,-65.78311,-15.2974
18.5,-66.488,-15.38033
18.6,-67.20129,-15.46413
18.7,-67.89001,-15.54684
18.8,-68.61617,-15.63071
18.9,-69.32724,-15.7136
19,-70.04225,-15.79736
19.1,-70.74872,-15.8806
19.2,-71.47495,-15.96382
19.3,-72.18472,-16.04744
19.4,-72.89315,-16.13034
19.5,-73.60749,-16.2141
19.6,-74.31261,-16.2969
19.7,-75.03296,-16.38068
19.8,-75.7478,-16.46364
19.9,-76.47228,-16.54721
20,-77.1807,-16.63054
20.1,-77.896,-16.71387
20.2,-78.63383,-16.79741
20.3,-79.33897,-16.88033
20.4,-80.05897,-16.96406
20.5,-80.78049,-17.0469
20.6,-81.50816,-17.13075
20.7,-82.23241,-17.21365
20.8,-82.96771,-17.29731
20.9,-83.69077,-17.38043
21,-84.40838,-17.46379
21.1,-85.15709,-17.54748
21.2,-85.87006,-17.63024
21.3,-86.60645,-17.71411
21.4,-87.32139,-17.7968
21.5,-88.06454,-17.88074
21.6,-88.78828,-17.96363
21.7,-89.53093,-18.04738
21.8,-90.27773,-18.13055
21.9,-91.02794,-18.21386
22,-91.77898,-18.29747
22.1,-92.533,-18.38044
22.2,-93.29996,-18.46405
22.3,-94.04041,-18.54693
22.4,-94.80405,-18.63074
22.5,-95.56152,-18.71371
22.6,-96.32624,-18.79737
22.7,-97.08258,-18.88052
22.8,-97.84513,-18.96392
22.9,-98.61344,-19.04736
23,-99.3828,-19.13029
23.08,-100.00353,-19.19749
23.081,-100.0108,-19.19833
23.082,-100.01806,-19.19917
23.182,-100.33134,-19.24894
23.282,-100.38091,-19.26937
23.382,-100.4162,-19.28459
23.482,-100.43368,-19.29782
23.582,-100.46305,-19.3093
23.682,-100.51536,-19.31963
23.782,-100.53717,-19.32889
23.882,-100.55432,-19.33765
23.982,-100.57206,-19.34609
24.082,-100.58888,-19.35369
24.182,-100.62591,-19.35996
24.282,-100.61782,-19.36555
24.382,-100.63398,-19.3709
24.482,-100.65118,-19.37629
24.582,-100.64574,-19.38131
24.682,-100.67892,-19.38591
24.782,-100.66103,-19.38955
24.882,-100.64625,-19.39237
24.982,-100.63676,-19.39494
25.082,-100.61594,-19.39729
25.182,-100.5996,-19.3991
25.282,-100.57991,-19.40059
25.382,-100.56171,-19.40197
25.482,-100.53632,-19.40316
25.582,-100.52318,-19.40424
25.682,-100.51635,-19.40523
25.782,-100.4698,-19.406
25.882,-100.46631,-19.40668
25.982,-100.43555,-19.40729
26.082,-100.41032,-19.40787
26.182,-100.39239,-19.40842
26.282,-100.37739,-19.40893
26.382,-100.34786,-19.40942
26.482,-100.32962,-19.40988
26.582,-100.28138,-19.41033
26.682,-100.32485,-19.41079
26.782,-100.25567,-19.41119
26.882,-100.25458,-19.4116
26.982,-100.21109,-19.41199
27.082,-100.22352,-19.41231
27.182,-100.20375,-19.4126
27.282,-100.17292,-19.41287
27.382,-100.1669,-19.41315
27.482,-100.13171,-19.41339
27.582,-100.14726,-19.41366
27.682,-100.08839,-19.41389
27.782,-100.12168,-19.41413
27.882,-100.0594,-19.41434
27.982,-100.06416,-19.41456
28.081,-100.04371,-19.41481
28.082,-100.04251,-19.41482
28.104,-100.03484,-19.41487
28.204,-100.85023,-19.46259
28.304,-101.96941,-19.55202
28.404,-102.92406,-19.63551
28.504,-103.84741,-19.71891
28.604,-104.7527,-19.80238
28.704,-105.62469,-19.88532
28.804,-106.49054,-19.96905
28.904,-107.35143,-20.05193
29.004,-108.17993,-20.13565
29.104,-109.02064,-20.21863
29.204,-109.85433,-20.30224
29.304,-110.66339,-20.38541
29.404,-111.4751,-20.46879
29.504,-112.24603,-20.55234
29.604,-113.0034,-20.63536
29.704,-113.74027,-20.71905
29.804,-114.47937,-20.8018
29.904,-115.25925,-20.88567
30.004,-116.01884,-20.9686
30.104,-116.80641,-21.05228
30.204,-117.58906,-21.13521
30.304,-118.36939,-21.21886
30.404,-119.14233,-21.30236
30.504,-119.9351,-21.38532
30.604,-120.73535,-21.46916
30.704,-121.50707,-21.55181
30.804,-122.29543,-21.63571
30.904,-123.0915,-21.71861
31.004,-123.87713,-21.80228
31.104,-124.67352,-21.8854
31.204,-125.44427,-21.96877
31.304,-126.25652,-22.05239
31.404,-127.01586,-22.1353
31.504,-127.8056,-22.21907
31.604,-128.57127,-22.30172
31.704,-129.36136,-22.38569
31.804,-130.14182,-22.4686
31.904,-130.92964,-22.55233
32.004,-131.69501,-22.63536
32.104,-132.48341,-22.71877
32.204,-133.26405,-22.80228
32.304,-134.02776,-22.88522
32.404,-134.81575,-22.96922
32.504,-135.56836,-23.0519
32.604,-136.35579,-23.13568
32.704,-137.10645,-23.21852
32.804,-137.88174,-23.30223
32.904,-138.64246,-23.3854
33.004,-139.4236,-23.46869
33.104,-140.19009,-23.5524
33.204,-140.95424,-23.63532
33.304,-141.72643,-23.7191
33.404,-142.48813,-23.80183
33.504,-143.27251,-23.88567
33.604,-144.03654,-23.96858
33.704,-144.79472,-24.05223
33.804,-145.5836,-24.13548
33.904,-146.35597,-24.21903
34.004,-147.1516,-24.3024
34.104,-147.89929,-24.38523
34.204,-148.70918,-24.46905
34.304,-149.50835,-24.55184
34.404,-150.3291,-24.63576
34.504,-151.12694,-24.71861
34.604,-151.92599,-24.80238
34.704,-152.71573,-24.88539
34.804,-153.5247,-24.96877
34.904,-154.34904,-25.05244
35.004,-155.14867,-25.13533
35.104,-155.95107,-25.21904
35.204,-156.76675,-25.30179
35.304,-157.58047,-25.38573
35.404,-158.38994,-25.46864
35.504,-159.20679,-25.55227
35.604,-160.02644,-25.63535
35.704,-160.84444,-25.71886
35.804,-161.66312,-25.80239
35.904,-162.47282,-25.88542
36.004,-163.29128,-25.96909
36.104,-164.09242,-26.05187
36.204,-164.91835,-26.13566
36.304,-165.73102,-26.21861
36.404,-166.5621,-26.30228
36.504,-167.37299,-26.38548
36.604,-168.19398,-26.46889
36.704,-169.01743,-26.55229
36.804,-169.82556,-26.63529
36.904,-170.65796,-26.71911
37.004,-171.45773,-26.80181
37.104,-172.30214,-26.88571
37.204,-173.12553,-26.9686
37.304,-173.95563,-27.05227
37.404,-174.78355,-27.13537
37.504,-175.61435,-27.21882
37.604,-176.43506,-27.30237
37.704,-177.26883,-27.38525
37.804,-178.1089,-27.46898
37.904,-178.94792,-27.5519
38.004,-179.79735,-27.63569
38.104,-180.62573,-27.71856
38.204,-181.44644,-27.8022
38.304,-182.29466,-27.88539
38.404,-183.14061,-27.96884
38.504,-183.98129,-28.05238
38.604,-184.82585,-28.1353
38.704,-185.65062,-28.21908
38.804,-186.49026,-28.30184
38.904,-187.34789,-28.38575
39.004,-188.17294,-28.46859
39.104,-189.01666,-28.55223
39.204,-189.84959,-28.63528
39.304,-190.68636,-28.7188
39.404,-191.54265,-28.80251
39.504,-192.35414,-28.88533
39.604,-193.21219,-28.9691
39.704,-194.048,-29.05173
39.804,-194.89674,-29.1357
39.904,-195.75409,-29.21867
40.004,-196.62224,-29.3023
40.104,-197.46129,-29.38533
40.204,-198.31059,-29.46878
40.304,-199.18163,-29.55241
40.404,-200.02919,-29.6354
40.504,-200.8934,-29.71922
40.604,-201.73749,-29.80189
40.704,-202.60648,-29.88564
40.804,-203.45529,-29.96855
40.904,-204.31306,-30.05235
41.004,-205.17111,-30.13539
41.104,-206.01001,-30.21869
41.204,-206.87044,-30.30245
41.304,-207.72527,-30.38541
41.404,-208.58183,-30.46913
41.504,-209.4171,-30.55178
41.604,-210.28752,-30.63569
41.704,-211.14604,-30.71853
41.804,-212.01501,-30.80226
41.904,-212.86858,-30.88552
42.004,-213.75104,-30.96878
42.104,-214.59921,-31.05237
42.204,-215.48108,-31.13529
42.304,-216.32965,-31.21911
42.404,-217.20651,-31.30186
42.504,-218.08568,-31.38572
42.604,-218.93872,-31.46859
42.704,-219.82892,-31.55228
42.804,-220.69252,-31.63554
42.904,-221.59134,-31.71885
43.004,-222.45236,-31.80237
43.104,-223.31918,-31.88526
43.204,-224.20287,-31.96903
43.304,-225.08763,-32.05182
43.404,-225.97417,-32.13565
43.504,-226.83287,-32.21856
43.604,-227.73615,-32.30242
43.704,-228.61125,-32.38529
43.804,-229.49855,-32.4688
43.904,-230.38184,-32.55239
44.004,-231.26326,-32.6353
44.104,-232.14503,-32.71906
44.204,-233.02258,-32.80176
44.304,-233.90446,-32.88572
44.404,-234.77493,-32.96862
44.504,-235.65506,-33.05231
44.604,-236.52995,-33.1354
44.704,-237.42548,-33.21874
44.804,-238.28001,-33.30241
44.904,-239.14558,-33.38536
45.004,-239.98766,-33.46902
45.104,-240.84772,-33.55184
45.204,-241.69827,-33.63566
45.304,-242.52496,-33.71855
45.404,-241.92154,-33.80231
45.504,-240.49712,-33.88542
45.604,-241.11391,-33.96885
45.704,-241.89191,-34.05235
45.804,-242.73891,-34.13512
45.904,-243.63681,-34.21926
46.004,-244.52423,-34.30181
46.104,-245.45456,-34.38566
46.204,-246.35931,-34.46858
46.304,-247.2588,-34.55233
46.404,-248.15187,-34.63543
46.504,-249.02779,-34.71874
46.604,-249.11061,-34.80244
46.704,-249.28052,-34.88526
46.804,-250.30252,-34.96902
46.904,-251.23546,-35.05198
47.004,-252.16603,-35.13567
47.104,-253.10356,-35.2185
47.204,-253.97714,-35.30224
47.304,-254.90376,-35.38543
47.404,-255.81241,-35.46882
47.504,-256.68631,-35.55231
47.604,-257.56863,-35.63528
47.704,-258.44354,-35.71906
47.804,-259.32217,-35.80184
47.904,-260.23941,-35.8858
48.004,-261.43835,-35.96856
48.104,-262.655,-36.05232
48.204,-263.85388,-36.13536
48.304,-265.0668,-36.21882
48.404,-266.29205,-36.30243
48.504,-267.44101,-36.38527
48.604,-268.50009,-36.46915
48.704,-269.45535,-36.5518
48.804,-270.49057,-36.63574
48.904,-271.50519,-36.71865
49.004,-272.57712,-36.8023
49.104,-273.58755,-36.88538
49.204,-274.67249,-36.96881
49.304,-275.7088,-37.05249
49.404,-276.77576,-37.13533
49.504,-277.80072,-37.21905
49.604,-278.9035,-37.30186
49.704,-279.96838,-37.38559
49.804,-281.04675,-37.46854
49.904,-282.06671,-37.55241
50.004,-283.12668,-37.63548
50.104,-284.09991,-37.71883
50.204,-285.13022,-37.80233
50.304,-286.11163,-37.88532
50.404,-287.10431,-37.96909
50.504,-288.07477,-38.0519
50.604,-289.07629,-38.1358
50.704,-290.05551,-38.21857
50.804,-291.03317,-38.30238
50.904,-292.01321,-38.38548
51.004,-292.95508,-38.4688
51.104,-293.90158,-38.55231
51.204,-294.84396,-38.63525
51.304,-295.79828,-38.71909
51.404,-296.71729,-38.80194
51.504,-297.68167,-38.88571
51.604,-298.5914,-38.9686
51.704,-299.52002,-39.05216
51.804,-300.42487,-39.13545
51.904,-301.34644,-39.21894
52.004,-302.21442,-39.30235
52.104,-303.09521,-39.38533
52.204,-303.96484,-39.46905
52.304,-304.75122,-39.55186
52.404,-305.5238,-39.63572
52.504,-306.21887,-39.71857
52.604,-306.96274,-39.8023
52.704,-307.67844,-39.88532
52.804,-308.38837,-39.96885
52.904,-309.06131,-40.0525
53.004,-309.69092,-40.13535
53.104,-310.32053,-40.21906
53.204,-310.9194,-40.30183
53.304,-311.7059,-40.38568
53.404,-312.65027,-40.46857
53.504,-313.65472,-40.55231
53.604,-314.6824,-40.63542
53.704,-315.70215,-40.7188
53.804,-316.7627,-40.80242
53.904,-317.79025,-40.88528
54.004,-318.81027,-40.96911
54.104,-319.81317,-41.05184
54.204,-320.75418,-41.13568
54.304,-321.60156,-41.21858
54.404,-322.49319,-41.30231
54.504,-323.50754,-41.38536
54.604,-324.5983,-41.46893
54.704,-325.68924,-41.55236
54.804,-326.85681,-41.63532
54.904,-328.10049,-41.7191
55.004,-329.39594,-41.80182
55.104,-330.73352,-41.88568
55.204,-332.10623,-41.96853
55.304,-333.54446,-42.0523
55.404,-334.9722,-42.13546
55.504,-336.44653,-42.21882
55.604,-337.91406,-42.30237
55.704,-339.40506,-42.38525
55.804,-340.9147,-42.46904
55.904,-342.45364,-42.55186
56.004,-343.98929,-42.6356
56.104,-345.53546,-42.71852
56.204,-347.09668,-42.80224
56.304,-348.6503,-42.8854
56.404,-350.19824,-42.96886
56.504,-351.7977,-43.05236
56.604,-353.27731,-43.13535
56.704,-354.84131,-43.21898
56.804,-356.39206,-43.30185
56.904,-357.94806,-43.38579
57.004,-359.45575,-43.46854
57.104,-360.96997,-43.55222
57.204,-362.50729,-43.6354
57.304,-364.02588,-43.71888
57.404,-365.5636,-43.80242
57.504,-367.05286,-43.88531
57.604,-368.55972,-43.9691
57.704,-370.06082,-44.05173
57.804,-371.51617,-44.13572
57.904,-373.02811,-44.21869
58.004,-374.47836,-44.30226
58.104,-375.9628,-44.38531
58.204,-377.44635,-44.46881
58.304,-378.95184,-44.55234
58.404,-380.4321,-44.63539
58.504,-381.95389,-44.71917
58.604,-383.42947,-44.8018
58.704,-384.95865,-44.88572
58.804,-386.42072,-44.96863
58.904,-387.95337,-45.05238
59.004,-389.45197,-45.13537
59.104,-390.97815,-45.21878
59.204,-392.51822,-45.30228
59.304,-394.06781,-45.38528
59.404,-395.60001,-45.46914
59.504,-397.14606,-45.55187
59.604,-398.81735,-45.63577
59.704,-400.48627,-45.71852
59.804,-402.23367,-45.80232
59.904,-403.95419,-45.88548
60.004,-405.71771,-45.96881
60.104,-407.48535,-46.05227
60.204,-409.25644,-46.13536
60.304,-411.03577,-46.21913
60.404,-412.79456,-46.30189
60.504,-414.59448,-46.38568
60.604,-416.39743,-46.46864
60.704,-418.20547,-46.55226
60.804,-419.99805,-46.63539
60.904,-421.84668,-46.71885
61.004,-423.66711,-46.80238
61.104,-425.48956,-46.88529
61.204,-427.34036,-46.96904
61.304,-429.19629,-47.05185
61.404,-431.07962,-47.13572
61.504,-432.93756,-47.21854
61.604,-434.83401,-47.30234
61.704,-436.69507,-47.38544
61.804,-438.58801,-47.46863
61.904,-440.50867,-47.55228
62.004,-442.39871,-47.63535
62.104,-444.31287,-47.71904
62.204,-446.2081,-47.80182
62.304,-448.1369,-47.88572
62.404,-450.03171,-47.96859
62.504,-451.96646,-48.05225
62.604,-453.88092,-48.13543
62.704,-455.79758,-48.21873
62.804,-457.74036,-48.30228
62.904,-459.67163,-48.38537
63.004,-461.62622,-48.46902
63.104,-463.54718,-48.55183
63.204,-465.51587,-48.63572
63.304,-467.45786,-48.71856
63.404,-469.40717,-48.80228
63.504,-471.35971,-48.88543
63.604,-473.31906,-48.96883
63.704,-475.29391,-49.05227
63.804,-477.25769,-49.13529
63.904,-479.25314,-49.21914
64.004,-481.22025,-49.30159
64.104,-483.22995,-49.38586
64.204,-485.19867,-49.46855
64.304,-487.20453,-49.5523
64.404,-489.20163,-49.6355
64.504,-491.18979,-49.7188
64.604,-493.2001,-49.80241
64.704,-495.18958,-49.88524
64.804,-497.18723,-49.96908
64.904,-499.19745,-50.05193
64.944,-500.0145,-50.08525
64.945,-500.03363,-50.08609
64.946,-500.0528,-50.08693
65.046,-500.39984,-50.12318
65.146,-499.89133,-50.12393
65.246,-499.54065,-50.12617
65.346,-499.25589,-50.12923
65.446,-499.08365,-50.13339
65.546,-498.9649,-50.13809
65.646,-498.86459,-50.14262
65.746,-498.79138,-50.14769
65.846,-498.77502,-50.15306
65.946,-498.76941,-50.15931
66.046,-498.81653,-50.16671
66.146,-498.94806,-50.17438
66.246,-499.00452,-50.18099
66.346,-499.05884,-50.18725
66.446,-499.09613,-50.19344
66.546,-499.13528,-50.19917
66.646,-499.16797,-50.20451
66.746,-499.19815,-50.21026
66.846,-499.24402,-50.2154
66.946,-499.25848,-50.22034
67.046,-499.29922,-50.22511
67.146,-499.3168,-50.23012
67.246,-499.37634,-50.23515
67.346,-499.42343,-50.2402
67.446,-499.46472,-50.24543
67.546,-499.54617,-50.25083
67.646,-499.60648,-50.25621
67.746,-499.64331,-50.26103
67.846,-499.71338,-50.26586
67.946,-499.74875,-50.27048
68.046,-499.78857,-50.27481
68.146,-499.81873,-50.27931
68.246,-499.87372,-50.28349
68.346,-499.9064,-50.28804
68.446,-499.98434,-50.29275
68.546,-500.01733,-50.29709
68.646,-500.03683,-50.301
68.746,-500.06885,-50.30455
68.846,-500.08392,-50.30788
68.946,-500.11093,-50.31098
69.046,-500.11374,-50.31419
69.146,-500.10712,-50.31699
69.246,-500.11832,-50.31948
69.346,-500.1015,-50.32211
69.446,-500.10486,-50.32487
69.546,-500.11456,-50.32737
69.646,-500.134,-50.33003
69.746,-500.12784,-50.33317
69.846,-500.19568,-50.33604
69.945,-500.14276,-50.33859
69.946,-500.14215,-50.33862
69.982,-500.13159,-50.33961
70.082,-498.56055,-50.29912
70.182,-494.89008,-50.21168
70.282,-491.16718,-50.1282
70.382,-487.84052,-50.04451
70.482,-484.64453,-49.96156
70.582,-481.63589,-49.87778
70.682,-478.5509,-49.79506
70.782,-475.69482,-49.71107
70.882,-472.73495,-49.62814
70.982,-470.00085,-49.54461
71.082,-467.36728,-49.46122
71.182,-464.74963,-49.37816
71.282,-462.1098,-49.2945
71.382,-459.51904,-49.21171
71.482,-456.91748,-49.12762
71.582,-454.35544,-49.04496
71.682,-451.85904,-48.96118
71.782,-449.327,-48.87819
71.882,-446.83716,-48.79463
71.982,-444.34631,-48.71127
72.082,-441.90573,-48.62812
72.182,-439.46161,-48.54451
72.282,-437.026,-48.46163
72.382,-434.60782,-48.37781
72.482,-432.19318,-48.29496
72.582,-429.78717,-48.21105
72.682,-427.39584,-48.12817
72.782,-425.03659,-48.04461
72.882,-422.66516,-47.96122
72.982,-420.33206,-47.87803
73.082,-417.98315,-47.79447
73.182,-415.65851,-47.71165
73.282,-413.33826,-47.62768
73.382,-411.05386,-47.54501
73.482,-408.70453,-47.4611
73.582,-406.43866,-47.37812
73.682,-404.14908,-47.29467
73.782,-401.86288,-47.21095
73.882,-399.60349,-47.12804
73.982,-397.31027,-47.04447
74.082,-395.06088,-46.96157
74.182,-392.80695,-46.87775
74.282,-390.62036,-46.79509
74.382,-388.40158,-46.71119
74.482,-386.2298,-46.62819
74.582,-384.01663,-46.54469
74.682,-381.82486,-46.46126
74.782,-379.64764,-46.37807
74.882,-377.4892,-46.29447
74.982,-375.39502,-46.21165
75.082,-373.25024,-46.12785
75.182,-371.14801,-46.04499
75.282,-369.04254,-45.96111
75.382,-366.95959,-45.87823
75.482,-364.87134,-45.79469
75.582,-362.77811,-45.71122
75.682,-360.71451,-45.62812
75.782,-358.66714,-45.5445
75.882,-356.64291,-45.46176
75.982,-354.61331,-45.37777
76.082,-352.63492,-45.29501
76.182,-350.63199,-45.21107
76.282,-348.65396,-45.12815
76.382,-346.67804,-45.0446
76.482,-344.69794,-44.96121
76.582,-342.77353,-44.87804
76.682,-340.82935,-44.79453
76.782,-338.91867,-44.71168
76.882,-336.99353,-44.62783
76.982,-335.13101,-44.5451
77.082,-333.20914,-44.46107
77.182,-331.34601,-44.37818
77.282,-329.46841,-44.29475
77.382,-327.65884,-44.21137
77.482,-325.83084,-44.12801
77.582,-324.00461,-44.0446
77.682,-322.26541,-43.9618
77.782,-320.51636,-43.87775
77.882,-318.81076,-43.79506
77.982,-317.1246,-43.7111
78.082,-315.45593,-43.62808
78.182,-313.79626,-43.54457
78.282,-312.17474,-43.46127
78.382,-310.56381,-43.37809
78.482,-308.94315,-43.29437
78.582,-307.34299,-43.21154
78.682,-305.74588,-43.12781
78.782,-304.16293,-43.04499
78.882,-302.57227,-42.96107
78.982,-301.01111,-42.87809
79.082,-299.45068,-42.79455
79.182,-297.87619,-42.71124
79.282,-296.30725,-42.62807
79.382,-294.78867,-42.54446
79.482,-293.24353,-42.4616
79.582,-291.71756,-42.3778
79.682,-290.22208,-42.2951
79.782,-288.71127,-42.21107
79.882,-287.25122,-42.12819
79.982,-285.72238,-42.04464
80.082,-284.23441,-41.96119
80.182,-282.75964,-41.87806
80.282,-281.32227,-41.79449
80.382,-279.88007,-41.71173
80.482,-278.39969,-41.6277
80.582,-276.97284,-41.54504
80.682,-275.52905,-41.46115
80.782,-274.11801,-41.37805
80.882,-272.67334,-41.29462
80.982,-271.27094,-41.21118
81.082,-269.86728,-41.12803
81.182,-268.45139,-41.04448
81.282,-267.08472,-40.96167
81.382,-265.68927,-40.87783
81.482,-264.34634,-40.7951
81.582,-262.99936,-40.71112
81.682,-261.69876,-40.62812
81.782,-260.40424,-40.54456
81.882,-259.16675,-40.46123
81.982,-257.97736,-40.37806
82.082,-256.79388,-40.29452
82.182,-255.74466,-40.21169
82.282,-254.74086,-40.12778
82.382,-253.76979,-40.04503
82.482,-252.7706,-39.96105
82.582,-251.78632,-39.87812
82.682,-250.79337,-39.79465
82.782,-249.81744,-39.71127
82.882,-248.82413,-39.62808
82.982,-247.83974,-39.54453
83.082,-246.82051,-39.46162
83.182,-245.75485,-39.3778
83.282,-244.71349,-39.29505
83.382,-243.6208,-39.21119
83.482,-242.56998,-39.12812
83.582,-241.49498,-39.04459
83.682,-240.42479,-38.96134
83.782,-239.35052,-38.87811
83.882,-238.26442,-38.79451
83.982,-237.19325,-38.71164
84.082,-236.11555,-38.62773
84.182,-235.04532,-38.54504
84.282,-233.97289,-38.46112
84.382,-232.90483,-38.37815
84.482,-231.82887,-38.29453
84.582,-230.75948,-38.21116
84.682,-229.70157,-38.12815
84.782,-228.61871,-38.04455
84.882,-227.55965,-37.96165
84.982,-226.48302,-37.87771
85.082,-225.42067,-37.79497
85.182,-224.35948,-37.71109
85.282,-223.28316,-37.62814
85.382,-222.20659,-37.54462
85.482,-221.15907,-37.46113
85.582,-220.09779,-37.37802
85.682,-219.04082,-37.29455
85.782,-217.97862,-37.21164
85.882,-216.91953,-37.12778
85.982,-215.86058,-37.04506
86.082,-214.75378,-36.96103
86.182,-213.69435,-36.87804
86.282,-212.62227,-36.79459
86.382,-211.58441,-36.71128
86.482,-210.5202,-36.62804
86.582,-209.45518,-36.54443
86.682,-208.38673,-36.46171
86.782,-207.32962,-36.37772
86.882,-206.29256,-36.29497
86.982,-205.19089,-36.21105
87.082,-204.14272,-36.12811
87.182,-203.08067,-36.04469
87.282,-202.01241,-35.96126
87.382,-200.97353,-35.87813
87.482,-199.89308,-35.79452
87.582,-198.84064,-35.71156
87.682,-197.77769,-35.6278
87.782,-196.73601,-35.54499
87.882,-195.66769,-35.46117
87.982,-194.61037,-35.37822
88.082,-193.54802,-35.29459
88.182,-192.51862,-35.21128
88.282,-191.46497,-35.12804
88.382,-190.43605,-35.0446
88.482,-189.39894,-34.96153
88.582,-188.34799,-34.87769
88.682,-187.32167,-34.79507
88.782,-186.28488,-34.71113
88.882,-185.29327,-34.62828
88.982,-184.28699,-34.54469
89.082,-183.31549,-34.46124
89.182,-182.37267,-34.37801
89.282,-181.45753,-34.2945
89.382,-180.5482,-34.21171
89.482,-179.61559,-34.12775
89.582,-178.71687,-34.04507
89.682,-177.80319,-33.96116
89.782,-176.90195,-33.87819
89.882,-175.97943,-33.79464
89.982,-175.06873,-33.71123
90.082,-174.16106,-33.62801
90.182,-173.25082,-33.54441
90.282,-172.36469,-33.46165
90.382,-171.43994,-33.3778
90.482,-170.54478,-33.29491
90.582,-169.6185,-33.21109
90.682,-168.75803,-33.12822
90.782,-167.85077,-33.04461
90.882,-166.95428,-32.96123
90.982,-166.07864,-32.87803
91.082,-165.16589,-32.7945
91.182,-164.27206,-32.71161
91.282,-163.40033,-32.62777
91.382,-162.51416,-32.54493
91.482,-161.60959,-32.46109
91.582,-160.73613,-32.37814
91.682,-159.86368,-32.29459
91.782,-158.98306,-32.21119
91.882,-158.12418,-32.12812
91.982,-157.23581,-32.04453
92.082,-156.34959,-31.96156
92.182,-155.4688,-31.87767
92.282,-154.60873,-31.79501
92.382,-153.74701,-31.71115
92.482,-152.87036,-31.62823
92.582,-152.01326,-31.54465
92.682,-151.16052,-31.46122
92.782,-150.30106,-31.378
92.882,-149.45213,-31.29455
92.982,-148.58141,-31.2116
93.082,-147.72375,-31.12776
93.182,-146.88678,-31.0451
93.282,-146.01604,-30.96109
93.382,-145.18463,-30.87824
93.482,-144.32962,-30.79463
93.582,-143.48007,-30.71126
93.682,-142.63953,-30.62814
93.782,-141.80356,-30.5445
93.882,-140.95923,-30.46173
93.982,-140.13451,-30.37786
94.082,-139.2921,-30.29503
94.182,-138.44574,-30.21107
94.282,-137.64183,-30.12815
94.382,-136.7843,-30.04463
94.482,-135.95683,-29.96117
94.582,-135.13347,-29.87802
94.682,-134.29713,-29.79458
94.782,-133.47749,-29.71163
94.882,-132.67735,-29.6279
94.982,-131.84895,-29.54494
95.082,-131.02068,-29.46106
95.182,-130.22031,-29.37823
95.282,-129.38478,-29.29462
95.382,-128.59087,-29.21132
95.482,-127.7514,-29.12805
95.582,-126.94559,-29.04443
95.682,-126.11906,-28.96172
95.782,-125.18562,-28.8778
95.882,-124.2765,-28.79506
95.982,-123.37505,-28.71116
96.082,-122.47511,-28.62807
96.182,-121.58438,-28.54464
96.282,-120.72789,-28.46116
96.382,-119.90493,-28.37818
96.482,-119.09288,-28.29442
96.582,-118.27638,-28.21159
96.682,-117.4299,-28.12781
96.782,-116.64675,-28.04498
96.882,-115.81673,-27.96107
96.982,-114.99816,-27.87813
97.082,-114.203,-27.79457
97.182,-113.38046,-27.71126
97.282,-112.58788,-27.62798
97.382,-111.76668,-27.54446
97.482,-110.98717,-27.46154
97.582,-110.16158,-27.37769
97.682,-109.37042,-27.29507
97.782,-108.57034,-27.21106
97.882,-107.77543,-27.12819
97.982,-106.97709,-27.04456
98.082,-106.16351,-26.96114
98.182,-105.37836,-26.87798
98.282,-104.58932,-26.7944
98.382,-103.81348,-26.71169
98.482,-103.0268,-26.62766
98.582,-102.23893,-26.54499
98.682,-101.46149,-26.46116
98.782,-100.70019,-26.37814
98.882,-99.91219,-26.29465
98.982,-99.14112,-26.21119
99.082,-98.36361,-26.12804
99.182,-97.58159,-26.04446
99.282,-96.83658,-25.96166
99.382,-96.0713,-25.87776
99.482,-95.31314,-25.79502
99.582,-94.51541,-25.7111
99.682,-93.75911,-25.62822
99.782,-93.01188,-25.54461
99.882,-92.25267,-25.46124
99.982,-91.4904,-25.37804
100.082,-90.70961,-25.29444
100.182,-89.96586,-25.2117
100.282,-89.22764,-25.12784
100.382,-88.48116,-25.04506
100.482,-87.73014,-24.96104
100.582,-86.98085,-24.87806
100.682,-86.24017,-24.79468
100.782,-85.48484,-24.71125
100.882,-84.7644,-24.62811
100.982,-84.02545,-24.54455
101.082,-83.3019,-24.46164
101.182,-82.55838,-24.37784
101.282,-81.82865,-24.29505
101.382,-81.10708,-24.21115
101.482,-80.38828,-24.12811
101.582,-79.64841,-24.04459
101.682,-78.91702,-23.96125
101.782,-78.20994,-23.87811
101.882,-77.48469,-23.79454
101.982,-76.76945,-23.71163
102.082,-76.0479,-23.62778
102.182,-75.31861,-23.54494
102.282,-74.59957,-23.46109
102.382,-73.90473,-23.3782
102.482,-73.16953,-23.29452
102.582,-72.4648,-23.21127
102.682,-71.76049,-23.12809
102.782,-71.04678,-23.0445
102.882,-70.33511,-22.96167
102.982,-69.61902,-22.87779
103.082,-68.93891,-22.79499
103.182,-68.21621,-22.71103
103.282,-67.52731,-22.62815
103.382,-66.8226,-22.54456
103.482,-66.12129,-22.46114
103.582,-65.42971,-22.37811
103.682,-64.70889,-22.29452
103.782,-64.00816,-22.2116
103.882,-63.32892,-22.12774
103.982,-62.65638,-22.04504
104.082,-61.94156,-21.96106
104.182,-61.26188,-21.87811
104.282,-60.59739,-21.7946
104.382,-59.93026,-21.71131
104.482,-59.27314,-21.62805
104.582,-58.62807,-21.54444
104.682,-57.99937,-21.46169
104.782,-57.37354,-21.37775
104.882,-56.79757,-21.29499
104.982,-56.24216,-21.21114
105.082,-55.70586,-21.12822
105.182,-55.17727,-21.04459
105.282,-54.60393,-20.96121
105.382,-54.01065,-20.87809
105.482,-53.42808,-20.79461
105.582,-52.8235,-20.71164
105.682,-52.2298,-20.62778
105.782,-51.63844,-20.54501
105.882,-51.05251,-20.46124
105.982,-50.51707,-20.37812
106.082,-49.92198,-20.29457
106.182,-49.38176,-20.21128
106.282,-48.79831,-20.12806
106.382,-48.2193,-20.04458
106.482,-47.67137,-19.96161
106.582,-47.08292,-19.87777
106.682,-46.50128,-19.79504
106.782,-45.94684,-19.71113
106.882,-45.3581,-19.62823
106.982,-44.79596,-19.54464
107.082,-44.22775,-19.46121
107.182,-43.6851,-19.37811
107.282,-43.12349,-19.29452
107.382,-42.55118,-19.2117
107.482,-42.01258,-19.12773
107.582,-41.45482,-19.04506
107.682,-40.917,-18.96112
107.782,-40.33939,-18.87814
107.882,-39.82571,-18.7947
107.982,-39.25066,-18.71124
108.082,-38.6795,-18.62804
108.182,-38.03296,-18.54451
108.282,-37.5052,-18.46159
108.382,-36.95425,-18.37777
108.482,-36.41936,-18.29496
108.582,-35.85188,-18.21104
108.682,-35.34265,-18.1282
108.782,-34.82086,-18.04464
108.882,-34.30934,-17.96126
108.982,-33.76807,-17.87801
109.082,-33.24255,-17.79443
109.182,-32.69869,-17.71152
109.282,-32.21796,-17.62771
109.382,-31.69088,-17.54502
109.482,-31.19433,-17.46105
109.582,-30.67999,-17.37811
109.682,-30.17508,-17.29467
109.782,-29.6971,-17.21123
109.882,-29.18372,-17.12808
109.982,-28.694,-17.04446
110.082,-28.21435,-16.96152
110.182,-27.74567,-16.87764
110.282,-27.2877,-16.795
110.382,-26.81034,-16.71112
110.482,-26.34097,-16.62812
110.582,-25.86776,-16.5446
110.682,-25.40171,-16.46124
110.782,-24.93231,-16.37808
110.882,-24.46936,-16.29444
110.982,-24.01054,-16.21158
111.082,-23.55875,-16.12774
111.182,-23.12,-16.04504
111.282,-22.65708,-15.96111
111.382,-22.21959,-15.87821
111.482,-21.77063,-15.79469
111.582,-21.37507,-15.71124
111.682,-21.02126,-15.62816
111.782,-20.67251,-15.54449
111.882,-20.27774,-15.46164
111.982,-19.87793,-15.37782
112.082,-19.47952,-15.29501
112.182,-19.07973,-15.21113
112.282,-18.69142,-15.12816
112.382,-18.31674,-15.0447
112.482,-17.95032,-14.96124
112.582,-17.61003,-14.87815
112.682,-17.28222,-14.79441
112.782,-17.02687,-14.71162
112.882,-16.92646,-14.62778
112.982,-16.57201,-14.54509
113.082,-16.18957,-14.46107
113.182,-15.82853,-14.37814
113.282,-15.47721,-14.29464
113.382,-15.16285,-14.21133
113.482,-14.85064,-14.12806
113.582,-14.52107,-14.04448
113.682,-14.20256,-13.96168
113.782,-13.8878,-13.87777
113.882,-13.57736,-13.79501
113.982,-13.27177,-13.71107
114.082,-12.96903,-13.62809
114.182,-12.65577,-13.54458
114.282,-12.35976,-13.46121
114.382,-12.07112,-13.37809
114.482,-11.80076,-13.29441
114.582,-11.51694,-13.2116
114.682,-11.26773,-13.12781
114.782,-11.00134,-13.04502
114.882,-10.78037,-12.96106
114.982,-10.58788,-12.87816
115.082,-10.37548,-12.79449
115.182,-10.18411,-12.71118
115.282,-9.97215,-12.62801
115.382,-9.76089,-12.54448
115.482,-9.51547,-12.46156
115.582,-9.27282,-12.37773
115.682,-9.00635,-12.29498
115.782,-8.72467,-12.21104
115.882,-8.48444,-12.1282
115.982,-8.21455,-12.04467
116.082,-7.95319,-11.9611
116.182,-7.69293,-11.87798
116.282,-7.43401,-11.7945
116.382,-7.16583,-11.71166
116.482,-6.89583,-11.62773
116.582,-6.64628,-11.54499
116.682,-6.38457,-11.46108
116.782,-6.11286,-11.37815
116.882,-5.8523,-11.29473
116.982,-5.59204,-11.21117
117.082,-5.34532,-11.12802
117.182,-5.07017,-11.04449
117.282,-4.80455,-10.96168
117.382,-4.57583,-10.87778
117.482,-4.3156,-10.79505
117.582,-4.08164,-10.71112
117.682,-3.8337,-10.6282
117.782,-3.59124,-10.54464
117.882,-3.35657,-10.46126
117.982,-3.11524,-10.37809
118.082,-2.88615,-10.29441
118.182,-2.64032,-10.21159
118.282,-2.40159,-10.12777
118.382,-2.18233,-10.04508
118.482,-1.9385,-9.96104
118.582,-1.72137,-9.87809
118.682,-1.48621,-9.79472
118.782,-1.26048,-9.71126
118.882,-1.04145,-9.62813
118.982,-0.83117,-9.54457
119.082,-0.60885,-9.46163
119.182,-0.39471,-9.37783
119.282,-0.2425,-9.29506
119.382,-0.14727,-9.21116
119.482,-0.07993,-9.12804
119.555,0.00038,-9.0673